Workbook

Sheet ReadMeFirst
A1: Auteur | B1: FC
A2: Source
A20: Sheets:
A21: Recap | C21: List of wordwhile experiments with (or without) exposed timber. Line 5: List of variable read by python to initialize compartments and write zone models (Cfast or Brisk) to be calcuated with the method
A22: Char Depth Graph | C22: Values and graphs, for each experiment of mesured char and calculated char with the method (automaticaly writed by the python program)
A23: Char mesurement | C23: Values of char mesurement in experiments from literature
A24: Char analyse | C24: Analyse of differences between char mesurements and calculations
A25: Gyps Protected | C25: Biblio on gyps protection
A28: Path of python program (PC Charm Community project): | F28: Espace partagé thèse FC (C:\Users\Francois.CONSIGNY\CSTBGroup\DSSF_Projet_These_Francois_Consigny - Documents) | Q28: 45545 | R28: \Calculs Feu\Programmes\python\Contribution_old\\Contribution_Brisk1
Q29: 45583 | R29: \Calculs Feu\Programmes\python\Contribution_old\\Contribution_Brisk2
D30: /!\ Warning if you run the python program verify the path used for program & models files according to your machine in the file Environnementxxxx.py: var BriskPath CurPath | Q30: 45604 | R30: \Calculs Feu\Programmes\python\Contribution_old\\Contribution_Brisk3
R31: \Calculs Feu\Programmes\python\Contribution_old\\Contribution_Brisk4
A33: Versions | B33: Date | C33: Descriptions | R33: Path program
A34: "atest" | B34: 45545 | C34: First Try of run with original (LG) method implemented with Brisk | I34: Base des tests de la méthode et échanges Canada. Correction HRR Fuel suivant email L.Girompaire du 21/05/24 | R34: \Calculs Feu\Programmes\python\Contribution_Brisk1\old\main.py -> \Calculs Feu\Programmes\python\Contribution_Brisk4\project\main_Contrib_brisk1.py
B35: 45581 | C35: Implementation of floor contribution and flag wood totaly consumed
B36: 45582 | C36: Add sheet Char Analyse and Variable HrrPUA in sheet Recap (column W)
A37: 241028 Recap Experiment_these | B37: 45593 | C37: Add sheet ReadMe First; Modif with Gyps fall-off Time | R37: \Calculs Feu\Programmes\python\Contribution_Brisk2\old\main5.py -> \Calculs Feu\Programmes\python\Contribution_Brisk4\project\main_Contrib_brisk2.py
C38: Modif of wood contribution law with material or recap (variables wd, cd, fd) density in place of default value (500kg/m3); Add sheet ReadMe First; Modif with Gyps fall-off Time
C39: Modif with adding Gyps fall-off Time
C40: Modif Excel with stat on Char analyse + comments on models prediction fails /succes
A41: 241108 Recap Experiment_these | B41: 45604 | C41: Modif of wood contribution law from Brisk Flux instead of Gas temperature (original method from LG/CD) | R41: \Calculs Feu\Programmes\python\Contribution_Brisk3\old\main6.py -> \Calculs Feu\Programmes\python\Contribution_Brisk4\project\main_Contrib_brisk3.py
C42: Modif of files name & directories in Pycharm project Contrib_brisk4 version: | R42: \Calculs Feu\Programmes\python\Contribution_Brisk4\project\main_Contrib_brisk4.py
D43: with x=4 pycharm project in Contrib_briskx directory main program = main_Contrib_briskx.py and called files Environmentx.py Briskcalx.py and Files_utilsx.py
D44: same names for all projects in \Calculs Feu\Programmes\python\Contribution_Briskx
D45: each directory \Contribution_Briskx organised with:
E46: \Models : Models generated and calculated with main_Contrib_briskx.py
E47: \projects : python files (main_Contrib_briskx.py…) & Pycharm project
E48: \old : old version of python files (mainy.py….) and models generated
C49: Modif of wood contribution law: from MLR / charring rate instead of external flux / charring rate (original method from LG/CD) see file \calculs Feu\241110_predictive_Timber_charing_Qcstb versus Qtemp_Qflux.xlsx
A50: various | B50: 2025 | C50: programm optimization & improvments | R50: \Calculs Feu\Programmes\python\Contribution_Bois_Brisk_fin\Project\main_Contrib_Brisk.py
C51: (WCTE & Interflam versions)
A52: 260102 Recap Experiment_these.xlsx | B52: 46054 | C52: Final version | R52: \Calculs Feu\Programmes\python\Contribution_Bois_Brisk\main_Contrib_Brisk.py
C53: adding Sheets :
D54: Char Comparaison x | G54: Graphs for papers and thesis manuscript
D55: Gyps protection | G55: Values, for each experiment of protection caracteristics and results of fall-off time and required thickness calculated with the method (automaticaly writed by the python program)
D56: Flux results | G56: Values, for each experiment of measured outside Flux and those calculated with the method (automaticaly writed by the python program)
D57: Heat of combustion | G57: Hc of fire from eperiment reports
C58: Integration of protected wood contribution, and exterior flux calculation

Sheet Recap
A3: Nomenclature | E3: Experimental Data (Input) | Z3: Experimental Data (Results) | BW3: Main findings / Conclusions | CB3: Compartment | CQ3: materials | EY3: openings (vents)
E4: Fire | H4: Area | J4: Exposed timber | T4: Sprinkler | W4: openings (vents) | Z4: Fire | AL4: Temperature | AM4: Event times | AY4: Wall char | BC4: Ceiling char | BG4: Floor char | BJ4: Beam char | BN4: Column char | BR4: Exterior Flux | CB4: Room geometry (interior dimensions) | CF4: Calculation | CK4: Ambient conditions | CQ4: Exposed Wood | CR4: Wall materials | CX4: Wood Wall caract. | DD4: Ceiling materials | DJ4: Wood Ceiling caract. | DQ4: Floor materials | DW4: Wood Floor caract. | EC4: Wood Beams | EN4: Wood Columns | EY4: Wall vents | EZ4: Wall vent 1 (i=1) | FH4: Wall vent (i=2) | FP4: Wall vent (i=3) | FX4: Wall vent (i=4) | GF4: Wall vent (i=5) | GN4: Wall vent (i=6) | GV4: Wall vent (i=7) | HD4: Wall vent (i=8) | HL4: Wall vent (i=9) | HT4: Wall vent (i=10) | IB4: Wall vent (i=11)
A5: Inst | B5: Aut | C5: Tnum | D5: Ref | E5: Fd | F5: Ft | G5: Hc | H5: Af | I5: At(b) | J5: Aexp/At | K5: Elem exposed | L5: Aexp/Aw | M5: Aexp/Aw-o | N5: Aexp/Af | O5: Wexposed/Awall | P5: Cexposed/Aceiling | Q5: Fexposed/Afloor | R5: Bexposed/Sbeam | S5: Coexposed/Scolomun | T5: n_sprinkler | U5: tsprinkler | V5: closed | W5: hv | X5: Av | Y5: O(b) | Z5: hrrtot_peak | AA5: hrrfuel_peak | AB5: hrrtimb_peak | AC5: HrrPUA | AD5: talpha | AE5: hrrfuel | AF5: hrrtimb | AG5: xfire | AH5: yfire | AI5: hfire | AJ5: tfire | AK5: mloss | AL5: Troom | AM5: dexp | AN5: fb_time | AO5: t_gyps_fo | AP5: t_wall_gyps_fo | AQ5: t_ceiling_gyps_fo | AR5: S_t_prot_wall | AS5: S_t_prot_ceiling | AT5: t_f_pr_wall | AU5: t_f_pr_ceiling | AV5: tdelam | AW5: Extinction | AX5: tchar_fin | AY5: Wchar_mean | AZ5: Wchar_min | BA5: Wchar_max | BB5: Wchar_speed | BC5: Cchar_mean | BD5: Cchar_min | BE5: Cchar_max | BF5: Cchar_speed | BG5: Fchar_mean | BH5: Fchar_min | BI5: Fchar_max | BJ5: Bchar_mean | BK5: Bchar_min | BL5: Bchar_max | BM5: Bchar_speed | BN5: Cochar_mean | BO5: Cochar_min | BP5: Cochar_max | BQ5: Bchar_speed | BR5: F_dist | BS5: F_wall | BT5: F_mode | BU5: T_ext | BV5: F_ext | CB5: Lr | CC5: Wr | CD5: Hr | CE5: C0 | CF5: tstep | CG5: ercontrol | CH5: ervent | CI5: interval | CJ5: scond | CK5: Zalt | CL5: Patm | CM5: Vwind | CN5: Wdir | CO5: Hamb | CP5: Tamb | CQ5: Aexp | CR5: Wl_mat | CS5: Wl_thick | CT5: Ws1_mat | CU5: Ws1_thick | CV5: Ws2_mat | CW5: Ws2_thick | CX5: Ww_t | CY5: Clw | CZ5: Huw | DA5: dw | DB5: Aw_wall | DC5: Wexposed | DD5: Cl_mat | DE5: Cl_thick | DF5: Cs1_mat | DG5: Cs1_thick | DH5: Cs2_mat | DI5: Cs2_thick | DJ5: Wc_t | DK5: Clc | DL5: Huc | DM5: dc | DN5: hc | DO5: Aw_ceiling | DP5: Cexposed | DQ5: Fl_mat | DR5: Fl_thick | DS5: Fs1_mat | DT5: Fs1_thick | DU5: Fs2_mat | DV5: Fs2_thick | DW5: Wf_t | DX5: Clf | DY5: Huf | DZ5: df | EA5: Aw_floor | EB5: Fexposed | EC5: Nb | ED5: Wb_t | EE5: Clb | EF5: Hub | EG5: db | EH5: lb_tot | EI5: wb | EJ5: hb | EK5: hb_exposed | EL5: Bface_exposed | EM5: Bexposed | EN5: Nco | EO5: Wco_t | EP5: Clco | EQ5: Huco | ER5: dco | ES5: lco_tot | ET5: wco | EU5: hco | EV5: hco_exposed | EW5: Coface_exposed | EX5: Coexposed | EY5: Nv | EZ5: wv1 | FA5: hv1 | FB5: sv1 | FC5: o_hv1 | FD5: Av1 | FE5: Nv1 | FF5: dv1 | FG5: Fv1 | FH5: wv2 | FI5: hv2 | FJ5: sv2 | FK5: o_hv2 | FL5: Av2 | FM5: Nv2 | FN5: dv2 | FO5: Fv2 | FP5: wv3 | FQ5: hv3 | FR5: sv3 | FS5: o_hv3 | FT5: Av3 | FU5: Nv3 | FV5: dv3 | FW5: Fv3 | FX5: wv4 | FY5: hv4 | FZ5: sv4 | GA5: o_hv4 | GB5: Av4 | GC5: Nv4 | GD5: dv4 | GE5: Fv4 | GF5: wv5 | GG5: hv5 | GH5: sv5 | GI5: o_hv5 | GJ5: Av5 | GK5: Nv5 | GL5: dv5 | GM5: Fv5 | GN5: wv6 | GO5: hv6 | GP5: sv6 | GQ5: o_hv6 | GR5: Av6 | GS5: Nv6 | GT5: dv6 | GU5: Fv6 | GV5: wv7 | GW5: hv7 | GX5: sv7 | GY5: o_hv7 | GZ5: Av7 | HA5: Nv7 | HB5: dv7 | HC5: Fv7 | HD5: wv8 | HE5: hv8 | HF5: sv8 | HG5: o_hv8 | HH5: Av8 | HI5: Nv8 | HJ5: dv8 | HK5: Fv8 | HL5: wv9 | HM5: hv9 | HN5: sv9 | HO5: o_hv9 | HP5: Av9 | HQ5: Nv9 | HR5: dv9 | HS5: Fv9 | HT5: wv10 | HU5: hv10 | HV5: sv10 | HW5: o_hv10 | HX5: Av10 | HY5: Nv10 | HZ5: dv10 | IA5: Fv10 | IB5: wv11 | IC5: hv11 | ID5: sv11 | IE5: o_hv11 | IF5: Av11 | IG5: Nv11 | IH5: dv11 | II5: Fv11
A6: [""] | B6: [""] | C6: [] | D6: [""] | E6: [MJ/m²] | F6: [""] | G6: [MJ/kg] | H6: [m²] | I6: [m²] | J6: % | K6: [""] | L6: % | M6: % | N6: % | O6: % | P6: % | Q6: % | R6: % | S6: % | T6: [] | U6: [mn] | V6: [Y/N] | W6: [m] | X6: [m²] | Y6: [m1/²] | Z6: [MW] | AA6: [MW] | AB6: [MW] | AC6: [kW/m²] | AD6: [s] | AE6: [path] | AF6: [path] | AG6: [m] | AH6: [m] | AI6: [m] | AJ6: [] | AK6: % | AL6: [°C] | AM6: [min] | AN6: [min] | AO6: [min; min; min] | AP6: [min] | AQ6: [min] | AR6: [min] | AS6: [min] | AT6: [min] | AU6: [min] | AV6: [min] | AW6: [Y/N] | AX6: [min] | AY6: [mm] | AZ6: [mm] | BA6: [mm] | BB6: [mm/min] | BC6: [mm] | BD6: [mm] | BE6: [mm] | BF6: [mm/min] | BG6: [mm] | BH6: [mm] | BI6: [mm] | BJ6: [mm] | BK6: [mm] | BL6: [mm] | BM6: [mm/min] | BN6: [mm] | BO6: [mm] | BP6: [mm] | BQ6: [mm/min] | BR6: [m] | BS6: [] | BT6: [] | BU6: [°C] | BV6: [kW/m²] | CB6: [m] | CC6: [m] | CD6: [m] | CE6: [m, m, m] | CF6: [sec] | CG6: [] | CH6: [] | CI6: [] | CJ6: [""] | CK6: [m] | CL6: [Pa] | CM6: [m/s] | CN6: [°] | CO6: % | CP6: [°C] | CQ6: [m²] | CR6: [""] | CS6: [mm.] | CT6: [""] | CU6: [mm.] | CV6: [""] | CW6: [mm.] | CX6: [""] | CY6: [""] | CZ6: % | DA6: [kg/m3] | DB6: [m²] | DC6: [m²] | DD6: [""] | DE6: [mm.] | DF6: [""] | DG6: [mm.] | DH6: [""] | DI6: [mm.] | DJ6: [""] | DK6: [""] | DL6: % | DM6: [kg/m3] | DN6: [MJ/kg] | DO6: [m²] | DP6: [m²] | DQ6: [""] | DR6: [mm.] | DS6: [""] | DT6: [mm.] | DU6: [""] | DV6: [mm.] | DW6: [""] | DX6: [""] | DY6: % | DZ6: [kg/m3] | EA6: [m²] | EB6: [m²] | EC6: [] | ED6: [""] | EE6: [""] | EF6: % | EG6: [kg/m3] | EH6: [m] | EI6: [m] | EJ6: [m] | EK6: [m] | EL6: [] | EM6: [m²] | EN6: [] | EO6: [""] | EP6: [""] | EQ6: % | ER6: [kg/m3] | ES6: [m] | ET6: [m] | EU6: [m] | EV6: [m] | EW6: [] | EX6: [m²] | EY6: [] | EZ6: [m] | FA6: [m] | FB6: [m] | FC6: [m] | FD6: [m²] | FE6: [] | FF6: [m] | FG6: [""] | FH6: [m] | FI6: [m] | FJ6: [m] | FK6: [m] | FL6: [m²] | FM6: [] | FN6: [m] | FO6: [""] | FP6: [m] | FQ6: [m] | FR6: [m] | FS6: [m] | FT6: [m²] | FU6: [] | FV6: [m] | FW6: [""] | FX6: [m] | FY6: [m] | FZ6: [m] | GA6: [m] | GB6: [m²] | GC6: [] | GD6: [m] | GE6: [""] | GF6: [m] | GG6: [m] | GH6: [m] | GI6: [m] | GJ6: [m²] | GK6: [] | GL6: [m] | GM6: [""] | GN6: [m] | GO6: [m] | GP6: [m] | GQ6: [m] | GR6: [m²] | GS6: [] | GT6: [m] | GU6: [""] | GV6: [m] | GW6: [m] | GX6: [m] | GY6: [m] | GZ6: [m²] | HA6: [] | HB6: [m] | HC6: [""] | HD6: [m] | HE6: [m] | HF6: [m] | HG6: [m] | HH6: [m²] | HI6: [] | HJ6: [m] | HK6: [""] | HL6: [m] | HM6: [m] | HN6: [m] | HO6: [m] | HP6: [m²] | HQ6: [] | HR6: [m] | HS6: [""] | HT6: [m] | HU6: [m] | HV6: [m] | HW6: [m] | HX6: [m²] | HY6: [] | HZ6: [m] | IA6: [""] | IB6: [m] | IC6: [m] | ID6: [m] | IE6: [m] | IF6: [m²] | IG6: [] | IH6: [m] | II6: [""]
A7: Institution | B7: Autor | C7: Test N° | D7: Reference | E7: Fire density | F7: Ignition Fuel (fuel type) | G7: Fuel heat of combustion | H7: Floor Area | I7: Comp Area (wall+Ceiling+floor) | J7: Exposed timber | K7: W- Wall(a) C- Ceiling B- Beam Co - Column | L7: Exposed Surface / wall surface | M7: Exposed Surface / wall surface - openings | N7: Exposed Surface / floor surface | O7: %of Wall Exposed | P7: % of Ceiling Exposed | Q7: %of Floor Exposed | R7: %of Beam Exposed | S7: %of Column exposed | T7: number of sprinkler | U7: time @ sprinkler activation | V7: opening closed at begining | W7: Opening Height | X7: Opening Area | Y7: Opening factor | Z7: Peak HRR Total | AA7: Peak HRR Fuel | AB7: Peak HRR Timber | AC7: HRRPUA Fuel | AD7: Fire growth rate (time to reach 1MW) | AE7: HRR Fuel [s,MW] | AF7: HRR Timber [s,MW] | AG7: Delta x (length) Fire position (default: center) | AH7: Delta y (width) Fire position (default: center) | AI7: fire height location (0=floor) | AJ7: Travelling fire: number of fires | AK7: mass loss | AL7: Peak Room Temperature | AM7: Duration of fire experiment | AN7: Fire Brigade travel time | AO7: time @ GB Fall off: Loc (Layer1, 2, 3) | AP7: time @ Wall GB Fall off | AQ7: time @ ceiling GB Fall off | AR7: Stprot_wall | AS7: Stprot_ceiling | AT7: tf,pr_wall | AU7: tf,pr_ceiling | AV7: time @ delamination | AW7: Auto-Extinction | AX7: time @ mesure | AY7: Mean | AZ7: Min | BA7: Max | BB7: Average | BC7: Mean | BD7: Min | BE7: Max | BF7: Average | BG7: Mean | BH7: Min | BI7: Max | BJ7: Mean | BK7: Min | BL7: Max | BM7: Average | BN7: Mean | BO7: Min | BP7: Max | BQ7: Average | BR7: Distance from windows of measure | BS7: wall with windows of measure | BT7: Mode of calculation of exterior flux ('above' or 'front'). It is absed on the position of the flux captor, if it is above the opening or in front of it. | BU7: Temperature | BV7: Flux | CB7: Length | CC7: Width | CD7: Height | CE7: Origin | CF7: Time step | CG7: Error Control | CH7: Vent flow error control | CI7: Excel Output interval | CJ7: Specific condition for calculation | CK7: altitude | CL7: atmospheric Pressure | CM7: wind velocity | CN7: wind direction | CO7: relative humidity | CP7: ambient Temp. | CQ7: Exposed Wood Surface | CR7: Lining materials | CS7: Lining thickness | CT7: Substrate #1 material | CU7: Substrate #1 thickness | CV7: Substrate #2 material | CW7: Substrate #2 thickness | CX7: Wood Type | CY7: Wood Class | CZ7: Humidity | DA7: Density | DB7: Surface | DC7: Exposed wood surface | DD7: Lining materials | DE7: Lining thickness | DF7: Substrate #1 material | DG7: Substrate #1 thickness | DH7: Substrate #2 material | DI7: Substrate #2 thickness | DJ7: Wood Type | DK7: Wood Class | DL7: Humidity | DM7: Density | DN7: Heat of combustion | DO7: Surface | DP7: Exposed wood | DQ7: Lining materials | DR7: Lining thickness | DS7: Substrate #1 material | DT7: Substrate #1 thickness | DU7: Substrate #2 material | DV7: Substrate #2 thickness | DW7: Wood Type | DX7: Wood Class | DY7: Humidity | DZ7: Density | EA7: Surface | EB7: Exposed wood | EC7: Number | ED7: Wood Type | EE7: Wood Class | EF7: Humidity | EG7: Density | EH7: total length | EI7: width | EJ7: height | EK7: Exposed height | EL7: Number of exposed face | EM7: Exposed wood surface | EN7: Number | EO7: Wood Type | EP7: Wood Class | EQ7: Humidity | ER7: Density | ES7: total length | ET7: width | EU7: height | EV7: Exposed height | EW7: Number of exposed face | EX7: Exposed wood surface | EY7: Number of wall vents | EZ7: width | FA7: height | FB7: sill | FC7: horizontal Offset in wall | FD7: rough opening surface | FE7: Number of repeated vents | FF7: Distance between repeated vents | FG7: Face location | FH7: width | FI7: height | FJ7: sill | FK7: horizontal Offset in wall | FL7: rough opening surface | FM7: Number of repeated vents | FN7: Distance between repeated vents | FO7: Face location | FP7: width | FQ7: height | FR7: sill | FS7: horizontal Offset in wall | FT7: rough opening surface | FU7: Number of repeated vents | FV7: Distance between repeated vents | FW7: Face location | FX7: width | FY7: height | FZ7: sill | GA7: horizontal Offset in wall | GB7: rough opening surface | GC7: Number of repeated vents | GD7: Distance between repeated vents | GE7: Face location | GF7: width | GG7: height | GH7: sill | GI7: horizontal Offset in wall | GJ7: rough opening surface | GK7: Number of repeated vents | GL7: Distance between repeated vents | GM7: Face location | GN7: width | GO7: height | GP7: sill | GQ7: horizontal Offset in wall | GR7: rough opening surface | GS7: Number of repeated vents | GT7: Distance between repeated vents | GU7: Face location | GV7: width | GW7: height | GX7: sill | GY7: horizontal Offset in wall | GZ7: rough opening surface | HA7: Number of repeated vents | HB7: Distance between repeated vents | HC7: Face location | HD7: width | HE7: height | HF7: sill | HG7: horizontal Offset in wall | HH7: rough opening surface | HI7: Number of repeated vents | HJ7: Distance between repeated vents | HK7: Face location | HL7: width | HM7: height | HN7: sill | HO7: horizontal Offset in wall | HP7: rough opening surface | HQ7: Number of repeated vents | HR7: Distance between repeated vents | HS7: Face location | HT7: width | HU7: height | HV7: sill | HW7: horizontal Offset in wall | HX7: rough opening surface | HY7: Number of repeated vents | HZ7: Distance between repeated vents | IA7: Face location | IB7: width | IC7: height | ID7: sill | IE7: horizontal Offset in wall | IF7: rough opening surface | IG7: Number of repeated vents | IH7: Distance between repeated vents | II7: Face location
A8: Carlton University | B8: McGregor 2013 | C8: 1 | D8: =CONCATENATE("McGregor_",C8) -> McGregor_1 | E8: 482 | F8: Propane | G8: 43.7 | H8: =CB8*CC8 -> 15.346181 | I8: =2*H8+2*(CB8+CC8)*CD8 -> 69.331334 | J8: =CQ8/I8 -> 0 | K8: 0 | L8: =CQ8/(2*(CB8+CC8)*CD8) -> 0 | M8: =CQ8/(2*(CB8+CC8)*CD8-X8) -> 0 | N8: =CQ8/H8 -> 0 | O8: =DC8/(2*(CB8+CC8)*CD8-X8) -> 0 | P8: =DP8/H8 -> 0 | Q8: =IF(ISNUMBER(EB8),EB8/H8,"") | V8: N | W8: =SUM(FD8*FA8+FL8*FI8+FT8*FQ8+GB8*FY8+GJ8*GG8+GR8*GO8)/X8 -> 2 | X8: =FD8+FL8+FT8+GB8+GJ8+GR8 -> 2.138 | Y8: =X8*SQRT(W8)/I8 -> 0.043610708 | Z8: 4.59 | AA8: 4 | AB8: 2.8 | AC8: =AA8/H8*1000 -> 260.65117 | AE8: 240823 HRR_Experiments.xlsx | AL8: 1157 | AM8: 119 | AO8: C2(31,41) W(31?,60?) | AP8: 60 | AQ8: 41 | AR8: 46.5 | AS8: 39.3 | AT8: 45.9 | AU8: 36.2 | AV8: 105; 115 | AW8: N | AX8: 119 | AY8: =ROUND('Char measurement'!U264,0) -> 26 | AZ8: 6 | BA8: 60 | BB8: 0.6 | BC8: =ROUND('Char measurement'!Q264,0) -> 34 | BD8: 12 | BE8: 55 | BF8: 1.67 | BW8: From the results of the tests that were conducted, the following conclusions could be drawn: 1. In protected room tests using furniture as the fuel, the fires self-extinguished when all combustibles were consumed and the CLT panels remained unaffected by the fire with no noticeable contribution to the growth, duration or intensity of the fire was observed. 2. In the protected room tests with propane as the fuel, once gypsum board protection began to fail, CLT panels contributed to the fire, increasing the energy release and production of smoke. 3. Increased fire growth rates were observed in rooms where CLT panels were unprotected, which reduced time to flashover. 4. Sprinklers can provide protection against fire growth for construction using CLT panels as sprinkler activation is expected to occur before significant fire growth and fire involvement o f exposed CLT panels. Sprinklers are recommended where exposed CLT panels are used. 5. Increased rates of energy release were observed where CLT panels were unprotected, approximately twofold in these tests. 6. Where charring caused delamination o f the CLT panels, energy release rates increased extending the duration of the room fire. This indicates that the CLT panels can contribute significantly to the fire load in a room and delamination could eventually lead to structural failure 156 7. Delamination o f the CLT panels provides fuel to the fire as it uncovers unbumt wood, which could lead to room flashover. Delamination occurred following failure o f the gypsum boards in the protected room with propane fire test as a result of extensive charring over a long period which the room temperature remained above 400°C. This caused the room to flashover for a second time. 8. The peak heat release rate in the unprotected room fire with furniture reached values that were considerably higher than the ventilation controlled peak indicating that combustion was taking place outside the room. 9. This research highlights fire hazards associated with construction using CLT panels in situations where no active fire protection is provided and over extended periods without response. In reality, for mid-rise applications that are the target for this research, the NBCC already includes active fire protection requirements that should prevent any contribution from CLT panels to the growth, duration and intensity o f room fires. | CB8: =3.5-2*CS8/1000 -> 3.4492 | CC8: =4.5-2*CS8/1000 -> 4.4492 | CD8: =2.5-(DE8+DR8+DT8)/1000 -> 2.446 | CF8: 0.25 | CP8: 5.5 | CQ8: =DC8+DP8+IF(ISNUMBER(EB8),EB8,0)+EM8+EX8 -> 0 | CR8: GYP1/2 | CS8: =2*12.7 -> 25.4 | CT8: CLT | CU8: =3*35 -> 105 | CV8: GYP1/2 | CW8: 12.7 | CX8: X-Lam (105-s3), | CY8: SPF 1950Fb MSR 35 x 89 mm members | DB8: =2*(CB8+CC8)*CD8-X8 -> 36.500973 | DD8: GYP1/2 | DE8: =2*12.7 -> 25.4 | DF8: CLT | DG8: =3*35 -> 105 | DH8: GYP1/2 | DI8: 12.7 | DJ8: X-Lam (105-s3), | DK8: SPF 1950Fb MSR 35 x 89 mm members | DO8: =CB8*CC8 -> 15.346181 | DQ8: fibre cement sheet | DR8: 12.7 | DS8: GYP1/2 | DT8: 15.9 | DU8: CLT | DV8: 105 | EA8: =CB8*CC8 -> 15.346181 | EB8: incl. in FL | EY8: 1 | EZ8: 1.069 | FA8: 2 | FB8: 0 | FC8: =(CB8-EZ8)/2 -> 1.1901 | FD8: =EZ8*FA8 -> 2.138 | FG8: Front
C9: 2 | D9: =CONCATENATE("McGregor_",C9) -> McGregor_2 | E9: 533 | F9: Residential fuel load | G9: 18.27 | H9: =CB9*CC9 -> 15.346181 | I9: =2*H9+2*(CB9+CC9)*CD9 -> 69.081745 | J9: =CQ9/I9 -> 0 | K9: 0 | L9: =CQ9/(2*(CB9+CC9)*CD9) -> 0 | M9: =CQ9/(2*(CB9+CC9)*CD9-X9) -> 0 | N9: =CQ9/H9 -> 0 | O9: =DC9/(2*(CB9+CC9)*CD9-X9) -> 0 | P9: =DP9/H9 -> 0 | Q9: =IF(ISNUMBER(EB9),EB9/H9,"") | V9: N | W9: =SUM(FD9*FA9+FL9*FI9+FT9*FQ9+GB9*FY9+GJ9*GG9+GR9*GO9)/X9 -> 2 | X9: =FD9+FL9+FT9+GB9+GJ9+GR9 -> 2.138 | Y9: =X9*SQRT(W9)/I9 -> 0.043768272 | Z9: =5.6 -> 5.6 | AA9: 5.49 | AC9: =AA9/H9*1000 -> 357.74374 | AK9: =379/E9 -> 0.71106942 | AM9: 60 | AR9: 46.5 | AS9: 39.3 | AT9: 45.9 | AU9: 36.2 | AW9: Y | AX9: 60 | CB9: =3.5-2*CS9/1000 -> 3.4492 | CC9: =4.5-2*CS9/1000 -> 4.4492 | CD9: =2.5-(DE9+DR9+DT9)/1000 -> 2.4302 | CP9: 17.5 | CQ9: =DC9+DP9+IF(ISNUMBER(EB9),EB9,0)+EM9+EX9 -> 0 | CR9: GYP1/2 | CS9: =2*12.7 -> 25.4 | CT9: CLT | CU9: =3*35 -> 105 | CV9: GYP1/2 | CW9: 12.7 | CX9: X-Lam (105-s3), | CY9: SPF 1950Fb MSR 35 x 89 mm members | DB9: =2*(CB9+CC9)*CD9-X9 -> 36.251383 | DD9: GYP1/2 | DE9: =2*12.7 -> 25.4 | DF9: CLT | DG9: =3*35 -> 105 | DH9: GYP1/2 | DI9: 12.7 | DJ9: X-Lam (105-s3), | DK9: SPF 1950Fb MSR 35 x 89 mm members | DO9: =CB9*CC9 -> 15.346181 | DQ9: HARDWOOD | DR9: 19 | DS9: fibre cement sheet | DT9: =2*12.7 -> 25.4 | DU9: GYP1/2 | DV9: 15.9 | EA9: =CB9*CC9 -> 15.346181 | EB9: incl. in FL | EY9: 1 | EZ9: 1.069 | FA9: 2 | FB9: 0 | FC9: =(CB9-EZ9)/2 -> 1.1901 | FD9: =EZ9*FA9 -> 2.138 | FG9: Front
C10: 3 | D10: =CONCATENATE("McGregor_",C10) -> McGregor_3 | E10: 182 | F10: Propane | G10: 43.7 | H10: =CB10*CC10 -> 15.75 | I10: =2*H10+2*(CB10+CC10)*CD10 -> 71.5 | J10: =CQ10/I10 -> 0.74981818 | K10: Wco;C;Fl | L10: =CQ10/(2*(CB10+CC10)*CD10) -> 1.3403 | M10: =CQ10/(2*(CB10+CC10)*CD10-X10) -> 1.4159844 | N10: =CQ10/H10 -> 3.4039365 | O10: =DC10/(2*(CB10+CC10)*CD10-X10) -> 1 | P10: =DP10/H10 -> 1 | Q10: =IF(ISNUMBER(EB10),EB10/H10,"") | V10: N | W10: =SUM(FD10*FA10+FL10*FI10+FT10*FQ10+GB10*FY10+GJ10*GG10+GR10*GO10)/X10 -> 2 | X10: =FD10+FL10+FT10+GB10+GJ10+GR10 -> 2.138 | Y10: =X10*SQRT(W10)/I10 -> 0.042287952 | Z10: 8.75 | AA10: 3 | AB10: =Z10-AA10 -> 5.75 | AC10: =AA10/H10*1000 -> 190.47619 | AE10: 240823 HRR_Experiments.xlsx | AL10: 982 | AM10: 60 | AW10: Y | AX10: 58 | AY10: =ROUND('Char measurement'!U284,0) -> 30 | AZ10: =AY10*0.75 -> 22.5 | BA10: 40 | BB10: 0.63 | BC10: =ROUND('Char measurement'!Q284,0) -> 20 | BD10: =BC10*0.75 -> 15 | BE10: 40 | BF10: =13/(24-5) -> 0.68421053 | CB10: 3.5 | CC10: 4.5 | CD10: 2.5 | CP10: 16 | CQ10: =DC10+DP10+IF(ISNUMBER(EB10),EB10,0)+EM10+EX10 -> 53.612 | CR10: CLT | CS10: 105 | CT10: GYP1/2 | CU10: 12.7 | CX10: X-Lam (105-s3), | CY10: SPF 1950Fb MSR 35 x 89 mm members | DB10: =2*(CB10+CC10)*CD10-X10 -> 37.862 | DC10: =2*(CB10+CC10)*CD10-X10 -> 37.862 | DD10: CLT | DE10: 105 | DF10: GYP1/2 | DG10: 12.7 | DJ10: X-Lam (105-s3), | DK10: SPF 1950Fb MSR 35 x 89 mm members | DO10: =CB10*CC10 -> 15.75 | DP10: =CB10*CC10 -> 15.75 | DQ10: fibre cement sheet | DR10: =2*12.7 -> 25.4 | DS10: GYP1/2 | DT10: 15.9 | DU10: CLT | DV10: 105 | EA10: =CB10*CC10 -> 15.75 | EB10: incl. in FL | EY10: 1 | EZ10: 1.069 | FA10: 2 | FB10: 0 | FC10: =(CB10-EZ10)/2 -> 1.2155 | FD10: =EZ10*FA10 -> 2.138 | FG10: Front
C11: 4 | D11: =CONCATENATE("McGregor_",C11) -> McGregor_4 | E11: 553 | F11: Residential fuel load | G11: 18.26 | H11: =CB11*CC11 -> 15.346181 | I11: =2*H11+2*(CB11+CC11)*CD11 -> 69.282364 | J11: =CQ11/I11 -> 0 | K11: Fl | L11: =CQ11/(2*(CB11+CC11)*CD11) -> 0 | M11: =CQ11/(2*(CB11+CC11)*CD11-X11) -> 0 | N11: =CQ11/H11 -> 0 | O11: =DC11/(2*(CB11+CC11)*CD11-X11) -> 0 | P11: =DP11/H11 -> 0 | Q11: =IF(ISNUMBER(EB11),EB11/H11,"") | V11: N | W11: =SUM(FD11*FA11+FL11*FI11+FT11*FQ11+GB11*FY11+GJ11*GG11+GR11*GO11)/X11 -> 2 | X11: =FD11+FL11+FT11+GB11+GJ11+GR11 -> 2.138 | Y11: =X11*SQRT(W11)/I11 -> 0.043641533 | Z11: 5.72 | AA11: 5.7 | AC11: =AA11/H11*1000 -> 371.42792 | AK11: =364/E11 -> 0.65822785 | AL11: 1081 | AM11: 54 | AR11: 46.5 | AS11: 39.3 | AT11: 45.9 | AU11: 36.2 | AW11: Y | AX11: 53 | CB11: =3.5-2*CS11/1000 -> 3.4492 | CC11: =4.5-2*CS11/1000 -> 4.4492 | CD11: =2.5-(DE11+DR11+DT11)/1000 -> 2.4429 | CP11: 27 | CQ11: =DC11+DP11+IF(ISNUMBER(EB11),EB11,0)+EM11+EX11 -> 0 | CR11: GYP1/2 | CS11: =2*12.7 -> 25.4 | CT11: CLT | CU11: =3*35 -> 105 | CV11: GYP1/2 | CW11: 12.7 | CX11: X-Lam (105-s3), | CY11: SPF 1950Fb MSR 35 x 89 mm members | DB11: =2*(CB11+CC11)*CD11-X11 -> 36.452003 | DD11: GYP1/2 | DE11: =2*12.7 -> 25.4 | DF11: CLT | DG11: =3*35 -> 105 | DH11: GYP1/2 | DI11: 12.7 | DJ11: X-Lam (105-s3), | DK11: SPF 1950Fb MSR 35 x 89 mm members | DO11: =CB11*CC11 -> 15.346181 | DQ11: HARDWOOD | DR11: 19 | DS11: fibre cement sheet | DT11: 12.7 | DU11: GYP1/2 | DV11: 15.9 | EA11: =CB11*CC11 -> 15.346181 | EB11: incl. in FL | EY11: 1 | EZ11: 1.069 | FA11: 2 | FB11: 0 | FC11: =(CB11-EZ11)/2 -> 1.1901 | FD11: =EZ11*FA11 -> 2.138 | FG11: Front
C12: 5 | D12: =CONCATENATE("McGregor_",C12) -> McGregor_5 | E12: 529 | F12: Residential fuel load | G12: 18.32 | H12: =CB12*CC12 -> 15.75 | I12: =2*H12+2*(CB12+CC12)*CD12 -> 71.5 | J12: =CQ12/I12 -> 0.74981818 | K12: Wco;C;Fl | L12: =CQ12/(2*(CB12+CC12)*CD12) -> 1.3403 | M12: =CQ12/(2*(CB12+CC12)*CD12-X12) -> 1.4159844 | N12: =CQ12/H12 -> 3.4039365 | O12: =DC12/(2*(CB12+CC12)*CD12-X12) -> 1 | P12: =DP12/H12 -> 1 | Q12: =IF(ISNUMBER(EB12),EB12/H12,"") | V12: N | W12: =SUM(FD12*FA12+FL12*FI12+FT12*FQ12+GB12*FY12+GJ12*GG12+GR12*GO12)/X12 -> 2 | X12: =FD12+FL12+FT12+GB12+GJ12+GR12 -> 2.138 | Y12: =X12*SQRT(W12)/I12 -> 0.042287952 | Z12: 7.69 | AA12: 5.6 | AB12: 6 | AC12: =AA12/H12*1000 -> 355.55556 | AK12: =366/E12 -> 0.69187146 | AL12: 1039 | AM12: 63 | AV12: 39 | AW12: N | AX12: 63 | AY12: =ROUND('Char measurement'!U309,0) -> 62 | AZ12: 40 | BA12: 70 | BB12: =24/(33-5) -> 0.85714286 | BC12: =ROUND('Char measurement'!Q309,0) -> 67 | BD12: 40 | BE12: 80 | BF12: =24/(30-5) -> 0.96 | CB12: 3.5 | CC12: 4.5 | CD12: 2.5 | CP12: 21 | CQ12: =DC12+DP12+IF(ISNUMBER(EB12),EB12,0)+EM12+EX12 -> 53.612 | CR12: CLT | CS12: 105 | CT12: GYP1/2 | CU12: 12.7 | CX12: X-Lam (105-s3), | CY12: SPF 1950Fb MSR 35 x 89 mm members | DB12: =2*(CB12+CC12)*CD12-X12 -> 37.862 | DC12: =2*(CB12+CC12)*CD12-X12 -> 37.862 | DD12: CLT | DE12: 105 | DF12: GYP1/2 | DG12: 12.7 | DJ12: X-Lam (105-s3), | DK12: SPF 1950Fb MSR 35 x 89 mm members | DO12: =CB12*CC12 -> 15.75 | DP12: =CB12*CC12 -> 15.75 | DQ12: HARDWOOD | DR12: 19 | DS12: fibre cement sheet | DT12: 12.7 | DU12: GYP1/2 | DV12: 15.9 | EA12: =CB12*CC12 -> 15.75 | EB12: incl. in FL | EY12: 1 | EZ12: 1.069 | FA12: 2 | FB12: 0 | FC12: =(CB12-EZ12)/2 -> 1.2155 | FD12: =EZ12*FA12 -> 2.138 | FG12: Front
B13: Medina 2014 | C13: 1 | D13: =CONCATENATE("Medina_",C13) -> Medina_1 | E13: 531.6 | F13: Residential fuel load | G13: 18.32 | H13: =CB13*CC13 -> 15.547445 | I13: =2*H13+2*(CB13+CC13)*CD13 -> 70.033252 | J13: =CQ13/I13 -> 0.2779991 | K13: Wc | L13: =CQ13/(2*(CB13+CC13)*CD13) -> 0.5 | M13: =CQ13/(2*(CB13+CC13)*CD13-X13) -> 0.52904863 | N13: =CQ13/H13 -> 1.2522431 | O13: =DC13/(2*(CB13+CC13)*CD13-X13) -> 0.52904863 | P13: =DP13/H13 -> 0 | Q13: =IF(ISNUMBER(EB13),EB13/H13,"") | V13: N | W13: =SUM(FD13*FA13+FL13*FI13+FT13*FQ13+GB13*FY13+GJ13*GG13+GR13*GO13)/X13 -> 2 | X13: =FD13+FL13+FT13+GB13+GJ13+GR13 -> 2.138 | Y13: =X13*SQRT(W13)/I13 -> 0.043173614 | Z13: 4.8 | AC13: =AA13/H13*1000 -> 0 | AL13: 1180 | AM13: 123 | AO13: C(75,87) | AQ13: 87 | AR13: 50 | AS13: 50 | AT13: 67.9 | AU13: 63.7 | AV13: 70 | AW13: N | AX13: 123 | AY13: =AVERAGE(80,71,74,73) -> 74.5 | AZ13: 71 | BA13: 80 | BB13: =AVERAGE(0.81914,0.729,0.68114,0.75386,0.426,0.73971,0.96157,0.46371) -> 0.69676625 | BC13: =AVERAGE(41,33) -> 37 | BD13: 33 | BE13: 41 | BW13: Many of these objectives were addressed after observations made during the three partially protected room fire tests and analysing the data output afterwards. The following conclusions were drawn from these tests. 1. All three room test had the same dimensions, ventilation opening factor, room content and were subjected to a non-standard fire. 2. The heat release rate during the tests with two walls exposed was much greater than the heat release rate of the test with only one wall exposed.3. The maximum HRR of Test 2 with unprotected walls facing each other was greater (6.3 MW) than the HRR of Test 1 (4.8 MW) in which the unprotected walls were adjacent to each other. Perhaps the greater radiation between walls in Test 2 due to a higher configuration or view factor led to higher burning rates. 4. Room temperatures during the early stages of the fire for all three tests were similar as only the room contents were involved in the fire. After flashover, the temperatures in the rooms with multiple unprotected walls decreased at a slower rate than the room with only one unprotected wall. 5. After an early integrity failure during Test 2, it was concluded that the use of fire rated caulking to seal lap joints connecting walls as well as any other CLT panel to panel connection is necessary. The lack of use of a sealant will allow hot gases to escape the fire room which could lead to flaming outside the room. 6. Premature delamination of CLT plies occurred in the first two tests with 2 walls unprotected. The first exposed CLT ply did not char fully before the adhesive failed, exposing the underneath ply and adding new fuel to the fire. Delamination of the plies was the reason for the second flashover during Test 1 and 2. Test 3 with only one wall exposed did not delaminate. 7. The CLT panels used for the construction of the third room were produced by a different manufacturer than the one which produced the CLT for Test 1 and 2. These panels had wider plies with more adhesive per ply which may have contributed to full ply charring without delamination.8. The charring rate of the unprotected walls was higher for Test 1 and 2 where the heat release rate was greater. The charring rate decreased linearly in all three tests as the thickness of the char layer developed. 9. Test 3 self-extinguished after all the contents in the room had been consumed with no major involvement of the CLT unprotected wall in the fire. The heat release rate and temperature in Test 1 decreased rapidly after the room contents were consumed but the fire re-ignited causing a second flashover due to burning of the second layer because of premature ply delamination. Tests 1 and 2 were manually put out by firefighters after the fire did not self-extinguish. 10. Test 3, with only the right wall unprotected, self-extinguish and performed similarly to the fully protected room test conducted by McGregor. 11. The results of the developed numerical model show that the model can accurately predict the structural failure of CLT walls when subjected to the standard timetemperature test. Overall the partially protected CLT room tests demonstrated that a certain percentage of the room interior surface area can be left unprotected without increasing the risk of fire spread or increased fire intensity. The study demonstrated that for a 4.5 x 3.5 x 2.5 m room with a door opening of 2.0 x 1.0 m with one wall unprotected accounting for 29.7 % of total room wall area performed similarly to a fully protected room and resulted in self-extinguishment after the room contents were consumed. Given the results from the room tests, the construction limitations on Cross Laminated Timber should be addressed. The walls and ceiling exceeded the required fire resistance rating of 1 hour for a building of a maximum of 6 storeys. Provided the walls and ceiling are properly ealed and protected with gypsum boards, CLT panels can be used in the construction of much taller buildings. The use of sprinklers is recommended as it ensures that fires will be suppressed with no fire department intervention. The premature delamination of plies is could be problematic but this should not be a concern if sprinklers are installed. | CB13: =3.5-CS13/1000 -> 3.4746 | CC13: =4.5-CS13/1000 -> 4.4746 | CD13: =2.5-(DE13+DR13+DT13)/1000 -> 2.4492 | CP13: -1 | CQ13: =DC13+DP13+IF(ISNUMBER(EB13),EB13,0)+EM13+EX13 -> 19.469181 | CR13: Gypsum Board, Type X (5/8 in) | CS13: =2*12.7 -> 25.4 | CT13: CLT | CU13: 105 | CX13: 105 mm thick 3-ply CLT | CY13: pruce-Pine-Fir (S-P-F) 1950Fb MSR 35x89 mm members | CZ13: 0.08 | DB13: =2*(CB13+CC13)*CD13-X13 -> 36.800361 | DC13: =(CB13+CC13)*CD13 -> 19.469181 | DD13: Gypsum Board, Type X (5/8 in) | DE13: =2*12.7 -> 25.4 | DF13: CLT | DG13: 105 | DJ13: 105 mm thick 3-ply CLT | DK13: pruce-Pine-Fir (S-P-F) 1950Fb MSR 35x89 mm members | DL13: 0.08 | DO13: =CB13*CC13 -> 15.547445 | DQ13: HARDWOOD | DR13: 12.7 | DS13: fibre cement sheet | DT13: 12.7 | DU13: CLT | DV13: 105 | EA13: =CB13*CC13 -> 15.547445 | EB13: incl. in FL | EY13: 1 | EZ13: 1.069 | FA13: 2 | FB13: 0 | FC13: =(CB13-EZ13)/2 -> 1.2028 | FD13: =EZ13*FA13 -> 2.138 | FG13: Front
C14: 2 | D14: =CONCATENATE("Medina_",C14) -> Medina_2 | E14: 531.6 | F14: Residential fuel load | H14: =CB14*CC14 -> 15.5214 | I14: =2*H14+2*(CB14+CC14)*CD14 -> 69.981161 | J14: =CQ14/I14 -> 0.31498191 | K14: Wo | L14: =CQ14/(2*(CB14+CC14)*CD14) -> 0.5660947 | M14: =CQ14/(2*(CB14+CC14)*CD14-X14) -> 0.59898325 | N14: =CQ14/H14 -> 1.4201554 | O14: =DC14/(2*(CB14+CC14)*CD14-X14) -> 0.59898325 | P14: =DP14/H14 -> 0 | Q14: =IF(ISNUMBER(EB14),EB14/H14,"") | V14: N | W14: =SUM(FD14*FA14+FL14*FI14+FT14*FQ14+GB14*FY14+GJ14*GG14+GR14*GO14)/X14 -> 2 | X14: =FD14+FL14+FT14+GB14+GJ14+GR14 -> 2.138 | Y14: =X14*SQRT(W14)/I14 -> 0.043205751 | Z14: 6.3 | AC14: =AA14/H14*1000 -> 0 | AL14: 1100 | AM14: 57 | AO14: W(31,Nof) C(27,45) | AQ14: 45 | AR14: 50 | AS14: 50 | AT14: 67.9 | AU14: 63.7 | AV14: 40 | AW14: N | AX14: 57 | AY14: =AVERAGE(60,54,53,57) -> 56 | AZ14: 54 | BA14: 60 | BB14: 0.9 | BC14: =11.5 -> 11.5 | BD14: 11 | BE14: 12 | CB14: =3.5-2*CS14/1000 -> 3.4492 | CC14: =4.5 -> 4.5 | CD14: =2.5-(DE14+DR14+DT14)/1000 -> 2.4492 | CP14: 19 | CQ14: =DC14+DP14+IF(ISNUMBER(EB14),EB14,0)+EM14+EX14 -> 22.0428 | CR14: Gypsum Board, Type X (5/8 in) | CS14: =2*12.7 -> 25.4 | CT14: CLT | CU14: 105 | CX14: 105 mm thick 3-ply CLT | CY14: pruce-Pine-Fir (S-P-F) 1950Fb MSR 35x89 mm members | CZ14: 0.105 | DB14: =2*(CB14+CC14)*CD14-X14 -> 36.800361 | DC14: =2*(CC14)*CD14 -> 22.0428 | DD14: Gypsum Board, Type X (5/8 in) | DE14: =2*12.7 -> 25.4 | DF14: CLT | DG14: 105 | DJ14: 105 mm thick 3-ply CLT | DK14: pruce-Pine-Fir (S-P-F) 1950Fb MSR 35x89 mm members | DL14: 0.105 | DO14: =CB14*CC14 -> 15.5214 | DQ14: HARDWOOD | DR14: 12.7 | DS14: fibre cement sheet | DT14: 12.7 | DU14: CLT | DV14: 105 | EA14: =CB14*CC14 -> 15.5214 | EB14: incl. in FL | EY14: 1 | EZ14: 1.069 | FA14: 2 | FB14: 0 | FC14: =(CB14-EZ14)/2 -> 1.1901 | FD14: =EZ14*FA14 -> 2.138 | FG14: Front
C15: 3 | D15: =CONCATENATE("Medina_",C15) -> Medina_3 | E15: 531.6 | F15: Residential fuel load | H15: =CB15*CC15 -> 15.6357 | I15: =2*H15+2*(CB15+CC15)*CD15 -> 71.1444 | J15: =CQ15/I15 -> 0.1581291 | K15: W | L15: =CQ15/(2*(CB15+CC15)*CD15) -> 0.28214581 | M15: =CQ15/(2*(CB15+CC15)*CD15-X15) -> 0.29813171 | N15: =CQ15/H15 -> 0.71950728 | O15: =DC15/(2*(CB15+CC15)*CD15-X15) -> 0.29813171 | P15: =DP15/H15 -> 0 | Q15: =IF(ISNUMBER(EB15),EB15/H15,"") | V15: N | W15: =SUM(FD15*FA15+FL15*FI15+FT15*FQ15+GB15*FY15+GJ15*GG15+GR15*GO15)/X15 -> 2 | X15: =FD15+FL15+FT15+GB15+GJ15+GR15 -> 2.138 | Y15: =X15*SQRT(W15)/I15 -> 0.04249932 | Z15: 4.3 | AC15: =AA15/H15*1000 -> 0 | AL15: 1097 | AM15: 80 | AO15: C(31,?) | AR15: 50 | AS15: 50 | AT15: 67.9 | AU15: 63.7 | AW15: Y | AX15: 80 | AY15: =AVERAGE(21,41,27,44) -> 33.25 | AZ15: 21 | BA15: 44 | BB15: =AVERAGE(0.75778,0.80484,0.67452,0.74796,0.50722,0.77348) -> 0.71096667 | CB15: =3.5-CS15/1000 -> 3.4746 | CC15: 4.5 | CD15: 2.5 | CP15: 23 | CQ15: =DC15+DP15+IF(ISNUMBER(EB15),EB15,0)+EM15+EX15 -> 11.25 | CR15: Gypsum Board, Type X (5/8 in) | CS15: =2*12.7 -> 25.4 | CT15: CLT | CU15: 105 | CX15: 105 mm thick 3-ply CLT | CY15: Structurlam Innovative Wood Specialists The panels were classified as V2 by the manufacturer which corresponds to a No. 1/No. 2 S-P-F lumber for the plies with grades parallel to the load (outer layers) and No. 3 S-P-F lumber for the plies with grades perpendicular to the load (inner layer). | CZ15: 0.135 | DB15: =2*(CB15+CC15)*CD15-X15 -> 37.735 | DC15: =CC15*CD15 -> 11.25 | DD15: Gypsum Board, Type X (5/8 in) | DE15: =2*12.7 -> 25.4 | DF15: CLT | DG15: 105 | DJ15: 105 mm thick 3-ply CLT | DK15: pruce-Pine-Fir (S-P-F) 1950Fb MSR 35x89 mm members | DL15: 0.135 | DO15: =CB15*CC15 -> 15.6357 | DQ15: HARDWOOD | DR15: 12.7 | DS15: fibre cement sheet | DT15: 12.7 | DU15: CLT | DV15: 105 | EA15: =CB15*CC15 -> 15.6357 | EB15: incl. in FL | EY15: 1 | EZ15: 1.069 | FA15: 2 | FB15: 0 | FC15: =(CB15-EZ15)/2 -> 1.2028 | FD15: =EZ15*FA15 -> 2.138 | FG15: Front
A16: NRCC&NIST | B16: Su & Al 2018a | C16: 1 | D16: =CONCATENATE($A$16,"_",C16) -> NRCC&NIST_1 | E16: 549 | F16: Residential fuel load | G16: 19.74 | H16: =CB16*CC16 -> 41.86 | I16: =2*H16+2*(CB16+CC16)*CD16 -> 157.7 | J16: =CQ16/I16 -> 0.0011778377 | K16: 0 | L16: =CQ16/(2*(CB16+CC16)*CD16) -> 0.0025107461 | M16: =CQ16/(2*(CB16+CC16)*CD16-X16) -> 0.0026404411 | N16: =CQ16/H16 -> 0.004437291 | O16: =DC16/(2*(CB16+CC16)*CD16-X16) -> 0 | P16: =DP16/H16 -> 0 | Q16: =IF(ISNUMBER(EB16),EB16/H16,"") -> 0.004437291 | V16: N | W16: =SUM(FD16*FA16+FL16*FI16+FT16*FQ16+GB16*FY16+GJ16*GG16+GR16*GO16)/X16 -> 1.9826061 | X16: =FD16+FL16+FT16+GB16+GJ16+GR16 -> 3.6338 | Y16: =X16*SQRT(W16)/I16 -> 0.032444983 | Z16: 9.5 | AC16: =AA16/H16*1000 -> 0 | AK16: 0.8 | AL16: 1200 | AM16: 134 | AO16: W(34-44,Nfo,Nfo) | AR16: 88.4 | AS16: 88.4 | AT16: 119.2 | AU16: 82.8 | AW16: Y | AX16: 134 | BG16: =AVERAGE(55,45,42) -> 47.333333 | BH16: 42 | BI16: 55 | BR16: 2.4, 4.8, 12 | BS16: Rear | BT16: Front | BV16: 40, 12, x | BW16: Test 1-1 and Test 1-2, with fully protected CLT compartments, defined the contribution of the movable fire load to the compartment fires and provided baselines to quantify the CLT contribution to the compartment fires in the tests involving various amounts of exposed CLT surfaces. Fully protecting the CLT compartments using gypsum board as the physical barrier was an effective means to delay and/or prevent the ignition and involvement of the timber structural elements in the fires, limiting and/or eliminating their contribution to the fires. In baseline Test 1-1, the three-layer gypsum board system completely prevented the ignition and involvement of the CLT structural elements in the fire and performed as well as non-combustible structural systems. In baseline Test 1-2, the two-layer gypsum board system successfully protected the CLT structure and limited the impact of the fire on the CLT structure with only surface char (less than 15 mm) in the rear section of the ceiling but no contribution to the compartment fire Ventilation conditions had significant impacts on the fire development in the compartments. In baseline Test 1-2, the larger ventilation opening accelerated combustion of the room contents, which intensified the exterior exposure, while shortening the intense burning duration. The peak temperatures and the heat fluxes inside the fire compartments were similar in both baseline tests but the fire decayed earlier in Test 1-2 with the larger opening. The heat release rate was higher but more intense burning occurred outside the fire compartment in Test 1-2 with the larger opening. The larger opening increased exterior fire exposure, which would have implications on the exterior façade and adjacent buildings. The smaller opening, as used in Test 1-1, delayed the onset of the decay phase, thereby extending the duration of the fullydeveloped phase Partially exposed CLT structure in Test 1-3, Test 1-4, Test 1-5 and Test 1-6 contributed to compartment fires to an extent depending on the area and orientation of exposed CLT surface and ventilation conditions. Note that Test 1-3 was terminated at 242 min (over 4 h), later than Test 1-4, Test 1-5 and Test 1-6. The impact of the ventilation opening size on CLT contribution to the compartment fires was clearly demonstrated by Test 1-3 and Test 1-5 with the same long wall exposed (W1 wall). The peak temperatures in the compartments were similar in both tests. However, the heat release rate and exterior heat fluxes were higher, and the fire exhibited a general trend of decay in Test 1-3 with the larger ventilation opening although there were two small transient increases due to the delamination of two plies of CLT from the exposed wall. In Test 1-5, with the smaller ventilation opening, more heat was trapped inside the compartment and, after the initial decay, a large re-flash occurred on the exposed wall with delamination of the second ply of the CLT, which caused the second flashover and induced the full involvement of the ceiling and all other walls in the fire. Over the full test duration, the volume (depth x area of the CLT charred in Test 1-5 with the smaller opening, was approximately 3.6 times of that in Test 1-3 with the larger opening although Test 1-5 was terminated 40 min earlier than Test 1-3 In all the tests with the exposed CLT surface, flashover occurred earlier than in the baseline. The exposed CLT panels translated to more fuel loads in addition to the movable fuel load (room contents) in the compartment. The peak compartment temperatures were similar to the baseline. However, the heat release rates and heat fluxes to the exterior façade were higher than the baseline. Other than Test 1-3, which had the larger opening and exhibited a general trend of decay, all tests with exposed CLT surface either had a second flashover due to the re-flash on the exposed surface or an intense fire continuously without any decay period. The CLT panels used in this series of the compartment tests were manufactured using 2 x 4 SPF lumber glued with a polyurethane adhesive (with a brand name of HBE). The delamination of unprotected (exposed) CLT panels led to re-flare and/or re growth of the fire after a period of decay in Test 1-3, Test 1-4 and Test 1-5 and no decay of the fire in Test 1-6 During Test 1-3, Test 1-5 and Test 1-6, the heat flux measured at 2.4 m and 4.8 m away from the rough opening reached 60 kW/m2 and 25 kW/m2, respectively. During Test 1-3, a video camera positioned at 9 m away from the opening was damaged due to its polycarbonate casing melting. Based on the configuration factor, the heat flux would be 9 kW/m2 at the camera location (9 m away). To support the fire service request for a large opening factor, a stand-off distance should be at least 12 m away from the rough opening for staging firefighting as the heat flux would be attenuated to 5 kW/m2 at 12 m away from the openin Although the CLT compartment fire tests were conducted without sprinklers, simulated thermal elements (STE) donated by FM Global were used in the tests to predict the time temperature response of a quick-response sprinkler element. In all the tests, the STEs reached 68 °C (a typical temperature rating for residential sprinklers) in between 1.2 min and 5.8 min while the fires were still limited to the first item ignited (the console table). Had sprinklers been installed in the tests, flashover would not have occurred with effective sprinkler operations. Recent fire tests, conducted in support of code development efforts of the International Code Council’s Ad Hoc Committee on Tall Wood Buildings by US Department of Agriculture’s Forest Products Laboratory at the Bureau of Alcohol, Tobacco, Firearms, and Explosives Fire Test Laboratory collected additional data on the effectiveness of sprinklers in controlling and suppressing fires in fully exposed CLT compartments | CB16: 4.6 | CC16: 9.1 | CD16: 2.7 | CJ16: 175 | CQ16: =DC16+DP16+IF(ISNUMBER(EB16),EB16,0)+EM16+EX16 -> 0.185745 | CR16: Gypsum Board, Type X (5/8 in) | CS16: =3*15.9 -> 47.7 | CT16: CLT | CU16: 175 | CX16: CLT 5-ply 35mm | CY16: ANSI/APA PRG 320, 2018 compliant | CZ16: =AVERAGE(7.2,8.2,7.9)/100 -> 0.077666667 | DB16: =2*(CB16+CC16)*CD16-X16 -> 70.3462 | DD16: Gypsum Board, Type X (5/8 in) | DE16: =3*15.9 -> 47.7 | DF16: CLT | DG16: 175 | DJ16: CLT 5-ply 35mm | DK16: ANSI/APA PRG 320, 2018 compliant | DL16: 0.062 | DO16: =CB16*CC16 -> 41.86 | DQ16: Plywood 7 mm | DR16: 7 | DS16: fibre cement sheet | DT16: =12.7*2 -> 25.4 | DU16: Gypsum Board, Type X (5/8 in) | DV16: =2*15.9 -> 31.8 | EA16: =CB16*CC16 -> 41.86 | EB16: =3*0.305*0.203 -> 0.185745 | EY16: 3 | EZ16: 1.8 | FA16: 2 | FB16: 0 | FC16: 1.8 | FD16: =EZ16*FA16 -> 3.6 | FG16: Rear | FH16: 0.13 | FI16: 0.13 | FJ16: 0.3 | FK16: 2.3 | FL16: =FH16*FI16 -> 0.0169 | FO16: Front | FP16: 0.13 | FQ16: 0.13 | FR16: 1.8 | FS16: 2.3 | FT16: =FP16*FQ16 -> 0.0169 | FW16: Front
C17: 2 | D17: =CONCATENATE($A$16,"_",C17) -> NRCC&NIST_2 | E17: 548 | H17: =CB17*CC17 -> 41.86 | I17: =2*H17+2*(CB17+CC17)*CD17 -> 157.7 | J17: =CQ17/I17 -> 0.0011778377 | K17: 0 | L17: =CQ17/(2*(CB17+CC17)*CD17) -> 0.0025107461 | M17: =CQ17/(2*(CB17+CC17)*CD17-X17) -> 0.0027828551 | N17: =CQ17/H17 -> 0.004437291 | O17: =DC17/(2*(CB17+CC17)*CD17-X17) -> 0 | P17: =DP17/H17 -> 0 | Q17: =IF(ISNUMBER(EB17),EB17/H17,"") -> 0.004437291 | V17: N | W17: =SUM(FD17*FA17+FL17*FI17+FT17*FQ17+GB17*FY17+GJ17*GG17+GR17*GO17)/X17 -> 1.9912624 | X17: =FD17+FL17+FT17+GB17+GJ17+GR17 -> 7.2338 | Y17: =X17*SQRT(W17)/I17 -> 0.064729023 | Z17: 12.4 | AC17: =AA17/H17*1000 -> 0 | AK17: 0.8 | AL17: 1200 | AM17: 104 | AO17: C(36-40,Nfo) | AR17: 66.1 | AS17: 66.1 | AT17: 98.9 | AU17: 75.2 | AW17: Y | AX17: 104 | BD17: 0.1 | BE17: 10 | BG17: =AVERAGE(46,35,35) -> 38.666667 | BH17: 35 | BI17: 46 | BR17: 2.4, 4.8, 12 | BS17: Rear | BT17: Front | BV17: 65, 22, x | CB17: 4.6 | CC17: 9.1 | CD17: 2.7 | CJ17: 175 | CQ17: =DC17+DP17+IF(ISNUMBER(EB17),EB17,0)+EM17+EX17 -> 0.185745 | CR17: Gypsum Board, Type X (5/8 in) | CS17: =2*15.9 -> 31.8 | CT17: CLT | CU17: 175 | CX17: CLT 5-ply 35mm | CY17: ANSI/APA PRG 320, 2018 compliant | CZ17: =AVERAGE(8,7.6,8.1)/100 -> 0.079 | DB17: =2*(CB17+CC17)*CD17-X17 -> 66.7462 | DD17: Gypsum Board, Type X (5/8 in) | DE17: =2*15.9 -> 31.8 | DF17: CLT | DG17: 175 | DJ17: CLT 5-ply 35mm | DK17: ANSI/APA PRG 320, 2018 compliant | DL17: 0.069 | DO17: =CB17*CC17 -> 41.86 | DQ17: Plywood 7 mm | DR17: 7 | DS17: fibre cement sheet | DT17: =12.7*2 -> 25.4 | DU17: Gypsum Board, Type X (5/8 in) | DV17: =2*15.9 -> 31.8 | EA17: =CB17*CC17 -> 41.86 | EB17: =3*0.305*0.203 -> 0.185745 | EY17: 3 | EZ17: 3.6 | FA17: 2 | FB17: 0 | FC17: 0.2 | FD17: =EZ17*FA17 -> 7.2 | FG17: Rear | FH17: 0.13 | FI17: 0.13 | FJ17: 0.3 | FK17: 2.3 | FL17: =FH17*FI17 -> 0.0169 | FO17: Front | FP17: 0.13 | FQ17: 0.13 | FR17: 1.8 | FS17: 2.3 | FT17: =FP17*FQ17 -> 0.0169 | FW17: Front
C18: 3 | D18: =CONCATENATE($A$16,"_",C18) -> NRCC&NIST_3 | E18: 556 | H18: =CB18*CC18 -> 41.86 | I18: =2*H18+2*(CB18+CC18)*CD18 -> 157.7 | J18: =CQ18/I18 -> 0.15580216 | K18: W | L18: =CQ18/(2*(CB18+CC18)*CD18) -> 0.33211679 | M18: =CQ18/(2*(CB18+CC18)*CD18-X18) -> 0.36811084 | N18: =CQ18/H18 -> 0.58695652 | O18: =DC18/(2*(CB18+CC18)*CD18-X18) -> 0.36811084 | P18: =DP18/H18 -> 0 | V18: N | W18: =SUM(FD18*FA18+FL18*FI18+FT18*FQ18+GB18*FY18+GJ18*GG18+GR18*GO18)/X18 -> 1.9912624 | X18: =FD18+FL18+FT18+GB18+GJ18+GR18 -> 7.2338 | Y18: =X18*SQRT(W18)/I18 -> 0.064729023 | Z18: 14.2 | AA18: =Z17 -> 12.4 | AB18: 3.5 | AC18: =AA18/H18*1000 -> 296.22551 | AL18: 1200 | AM18: 242 | AO18: C(25-35, Nfo) | AR18: 66.1 | AS18: 66.1 | AT18: 98.9 | AU18: 75.2 | AV18: 90 ; 190 | AW18: Y | AX18: 70 | AY18: =AVERAGE(BA18,AZ18) -> 27.5 | AZ18: 20 | BA18: 35 | BR18: 2.4, 4.8, 12 | BS18: Rear | BT18: Front | BV18: 65, 25, x | CB18: 4.6 | CC18: 9.1 | CD18: 2.7 | CQ18: =DC18+DP18+IF(ISNUMBER(EB18),EB18,0)+EM18+EX18 -> 24.57 | CR18: Gypsum Board, Type X (5/8 in) | CS18: =2*15.9 -> 31.8 | CT18: CLT | CU18: 175 | CX18: CLT 5-ply 35mm | CY18: ANSI/APA PRG 320, 2018 compliant | CZ18: =AVERAGE(8.2,7.5,8.6,6.8)/100 -> 0.07775 | DB18: =2*(CB18+CC18)*CD18-X18 -> 66.7462 | DC18: =CC18*CD18 -> 24.57 | DD18: Gypsum Board, Type X (5/8 in) | DE18: =2*15.9 -> 31.8 | DF18: CLT | DG18: 175 | DJ18: CLT 5-ply 35mm | DK18: ANSI/APA PRG 320, 2018 compliant | DL18: 0.064 | DO18: =CB18*CC18 -> 41.86 | DQ18: Plywood 7 mm | DR18: 7 | DS18: fibre cement sheet | DT18: =12.7*2 -> 25.4 | DU18: Gypsum Board, Type X (5/8 in) | DV18: =2*15.9 -> 31.8 | EA18: =CB18*CC18 -> 41.86 | EB18: incl. in FL | EY18: 3 | EZ18: 3.6 | FA18: 2 | FB18: 0 | FC18: 0.2 | FD18: =EZ18*FA18 -> 7.2 | FG18: Rear | FH18: 0.13 | FI18: 0.13 | FJ18: 0.3 | FK18: 2.3 | FL18: =FH18*FI18 -> 0.0169 | FO18: Front | FP18: 0.13 | FQ18: 0.13 | FR18: 1.8 | FS18: 2.3 | FT18: =FP18*FQ18 -> 0.0169 | FW18: Front
C19: 4 | D19: =CONCATENATE($A$16,"_",C19) -> NRCC&NIST_4 | E19: 548 | H19: =CB19*CC19 -> 41.86 | I19: =2*H19+2*(CB19+CC19)*CD19 -> 157.7 | J19: =CQ19/I19 -> 0.26544071 | K19: C | L19: =CQ19/(2*(CB19+CC19)*CD19) -> 0.5658286 | M19: =CQ19/(2*(CB19+CC19)*CD19-X19) -> 0.59505702 | N19: =CQ19/H19 -> 1 | O19: =DC19/(2*(CB19+CC19)*CD19-X19) -> 0 | P19: =DP19/H19 -> 1 | V19: N | W19: =SUM(FD19*FA19+FL19*FI19+FT19*FQ19+GB19*FY19+GJ19*GG19+GR19*GO19)/X19 -> 1.9826061 | X19: =FD19+FL19+FT19+GB19+GJ19+GR19 -> 3.6338 | Y19: =X19*SQRT(W19)/I19 -> 0.032444983 | Z19: 13.1 | AA19: =Z16 -> 9.5 | AB19: 5.5 | AC19: =AA19/H19*1000 -> 226.94697 | AL19: 1200 | AM19: 159 | AO19: W(46-73,Nfo,Nfo) | AR19: 88.4 | AS19: 88.4 | AT19: 119.2 | AV19: 150 | AW19: N | AX19: 159 | BC19: =AVERAGE('Char measurement'!B122:E129) -> 78.625 | BD19: =MIN('Char measurement'!B122:E129) -> 68 | BE19: =MAX('Char measurement'!B122:E129) -> 90 | BF19: =BC19/AX19 -> 0.49449686 | BR19: 2.4, 4.8, 12 | BS19: Rear | BT19: Front | BV19: 45, 17, x | CB19: 4.6 | CC19: 9.1 | CD19: 2.7 | CQ19: =DC19+DP19+IF(ISNUMBER(EB19),EB19,0)+EM19+EX19 -> 41.86 | CR19: Gypsum Board, Type X (5/8 in) | CS19: =3*15.9 -> 47.7 | CT19: CLT | CU19: 175 | CX19: CLT 5-ply 35mm | CY19: ANSI/APA PRG 320, 2018 compliant | CZ19: =AVERAGE(9.9,8.7,8.8,8.8)/100 -> 0.0905 | DB19: =2*(CB19+CC19)*CD19-X19 -> 70.3462 | DD19: CLT | DE19: 175 | DJ19: CLT 5-ply 35mm | DK19: ANSI/APA PRG 320, 2018 compliant | DL19: 0.072 | DO19: =CB19*CC19 -> 41.86 | DP19: =CB19*CC19 -> 41.86 | DQ19: Plywood 7 mm | DR19: 7 | DS19: fibre cement sheet | DT19: =12.7*2 -> 25.4 | DU19: Gypsum Board, Type X (5/8 in) | DV19: =2*15.9 -> 31.8 | EA19: =CB19*CC19 -> 41.86 | EB19: incl. in FL | EY19: 3 | EZ19: 1.8 | FA19: 2 | FB19: 0 | FC19: 1.8 | FD19: =EZ19*FA19 -> 3.6 | FG19: Rear | FH19: 0.13 | FI19: 0.13 | FJ19: 0.3 | FK19: 2.3 | FL19: =FH19*FI19 -> 0.0169 | FO19: Front | FP19: 0.13 | FQ19: 0.13 | FR19: 1.8 | FS19: 2.3 | FT19: =FP19*FQ19 -> 0.0169 | FW19: Front
C20: 5 | D20: =CONCATENATE($A$16,"_",C20) -> NRCC&NIST_5 | E20: 556 | H20: =CB20*CC20 -> 41.86 | I20: =2*H20+2*(CB20+CC20)*CD20 -> 157.7 | J20: =CQ20/I20 -> 0.15580216 | K20: W | L20: =CQ20/(2*(CB20+CC20)*CD20) -> 0.33211679 | M20: =CQ20/(2*(CB20+CC20)*CD20-X20) -> 0.3492726 | N20: =CQ20/H20 -> 0.58695652 | O20: =DC20/(2*(CB20+CC20)*CD20-X20) -> 0.3492726 | P20: =DP20/H20 -> 0 | V20: N | W20: =SUM(FD20*FA20+FL20*FI20+FT20*FQ20+GB20*FY20+GJ20*GG20+GR20*GO20)/X20 -> 1.9826061 | X20: =FD20+FL20+FT20+GB20+GJ20+GR20 -> 3.6338 | Y20: =X20*SQRT(W20)/I20 -> 0.032444983 | Z20: 9.6 | AA20: =Z16 -> 9.5 | AB20: 9.5 | AC20: =AA20/H20*1000 -> 226.94697 | AL20: 1200 | AM20: 202 | AO20: W(50-70,155-180,185-195) C(32-45,70-144,144-155) | AP20: 185 | AQ20: 144 | AR20: 88.4 | AS20: 88.4 | AT20: 119.2 | AU20: 82.8 | AV20: 140 | AW20: N | AX20: 202 | AY20: =AVERAGE('Char measurement'!G134:N137) -> 131.28125 | AZ20: =MIN('Char measurement'!G134:N137) -> 102 | BA20: =MAX('Char measurement'!G134:N137) -> 141 | BB20: =AY20/AX20 -> 0.64990718 | BC20: =AVERAGE('Char measurement'!B134:E141) -> 61.28125 | BD20: =MIN('Char measurement'!B134:E141) -> 25 | BE20: =MAX('Char measurement'!B134:E141) -> 79 | BF20: =BC20/AX20 -> 0.30337252 | BR20: 2.4, 4.8, 12 | BS20: Rear | BT20: Front | BV20: 40, 15, x | CB20: 4.6 | CC20: 9.1 | CD20: 2.7 | CQ20: =DC20+DP20+IF(ISNUMBER(EB20),EB20,0)+EM20+EX20 -> 24.57 | CR20: Gypsum Board, Type X (5/8 in) | CS20: =3*15.9 -> 47.7 | CT20: CLT | CU20: 175 | CX20: CLT 5-ply 35mm | CY20: ANSI/APA PRG 320, 2018 compliant | CZ20: =AVERAGE(7.8,7.7,7.6,7.9)/100 -> 0.0775 | DB20: =2*(CB20+CC20)*CD20-X20 -> 70.3462 | DC20: =CC20*CD20 -> 24.57 | DD20: Gypsum Board, Type X (5/8 in) | DE20: =3*15.9 -> 47.7 | DF20: CLT | DG20: 175 | DJ20: CLT 5-ply 35mm | DK20: ANSI/APA PRG 320, 2018 compliant | DL20: 0.079 | DO20: =CB20*CC20 -> 41.86 | DQ20: Plywood 7 mm | DR20: 7 | DS20: fibre cement sheet | DT20: =12.7*2 -> 25.4 | DU20: Gypsum Board, Type X (5/8 in) | DV20: =2*15.9 -> 31.8 | EA20: =CB20*CC20 -> 41.86 | EB20: incl. in FL | EY20: 3 | EZ20: 1.8 | FA20: 2 | FB20: 0 | FC20: 1.8 | FD20: =EZ20*FA20 -> 3.6 | FG20: Rear | FH20: 0.13 | FI20: 0.13 | FJ20: 0.3 | FK20: 2.3 | FL20: =FH20*FI20 -> 0.0169 | FO20: Front | FP20: 0.13 | FQ20: 0.13 | FR20: 1.8 | FS20: 2.3 | FT20: =FP20*FQ20 -> 0.0169 | FW20: Front
C21: 6 | D21: =CONCATENATE($A$16,"_",C21) -> NRCC&NIST_6 | E21: 550 | H21: =CB21*CC21 -> 41.86 | I21: =2*H21+2*(CB21+CC21)*CD21 -> 157.7 | J21: =CQ21/I21 -> 0.42124287 | K21: W;C | L21: =CQ21/(2*(CB21+CC21)*CD21) -> 0.89794539 | M21: =CQ21/(2*(CB21+CC21)*CD21-X21) -> 0.94432962 | N21: =CQ21/H21 -> 1.5869565 | O21: =DC21/(2*(CB21+CC21)*CD21-X21) -> 0.3492726 | P21: =DP21/H21 -> 1 | V21: N | W21: =SUM(FD21*FA21+FL21*FI21+FT21*FQ21+GB21*FY21+GJ21*GG21+GR21*GO21)/X21 -> 1.9826061 | X21: =FD21+FL21+FT21+GB21+GJ21+GR21 -> 3.6338 | Y21: =X21*SQRT(W21)/I21 -> 0.032444983 | Z21: 12.9 | AA21: =Z16 -> 9.5 | AB21: 10 | AC21: =AA21/H21*1000 -> 226.94697 | AL21: 1200 | AM21: 160 | AO21: W3(55-108,85-120,125) W4(77-120,93-120,125-130) | AP21: 125 | AR21: 88.4 | AS21: 88.4 | AT21: 119.2 | AW21: N | AX21: 160 | AY21: =AVERAGE('Char measurement'!G146:N149) -> 122.53125 | AZ21: =MIN('Char measurement'!G146:N149) -> 88 | BA21: =MAX('Char measurement'!G146:N149) -> 143 | BB21: =AY21/AX21 -> 0.76582031 | BC21: =AVERAGE('Char measurement'!B146:E153) -> 127.51613 | BD21: =MIN('Char measurement'!B146:E153) -> 13 | BE21: =MAX('Char measurement'!B146:E153) -> 154 | BF21: =BC21/AX21 -> 0.79697581 | BR21: 2.4, 4.8, 12 | BS21: Rear | BT21: Front | BV21: 55, 20, x | CB21: 4.6 | CC21: 9.1 | CD21: 2.7 | CQ21: =DC21+DP21+IF(ISNUMBER(EB21),EB21,0)+EM21+EX21 -> 66.43 | CR21: Gypsum Board, Type X (5/8 in) | CS21: =3*15.9 -> 47.7 | CT21: CLT | CU21: 175 | CX21: CLT 5-ply 35mm | CY21: ANSI/APA PRG 320, 2018 compliant | CZ21: =AVERAGE(7.2,7.7,6.4,6.7)/100 -> 0.07 | DB21: =2*(CB21+CC21)*CD21-X21 -> 70.3462 | DC21: =CC21*CD21 -> 24.57 | DD21: CLT | DE21: 175 | DJ21: CLT 5-ply 35mm | DK21: ANSI/APA PRG 320, 2018 compliant | DL21: 0.079 | DO21: =CB21*CC21 -> 41.86 | DP21: =CB21*CC21 -> 41.86 | DQ21: Plywood 7 mm | DR21: 7 | DS21: fibre cement sheet | DT21: =12.7*2 -> 25.4 | DU21: Gypsum Board, Type X (5/8 in) | DV21: =2*15.9 -> 31.8 | EA21: =CB21*CC21 -> 41.86 | EB21: incl. in FL | EY21: 3 | EZ21: 1.8 | FA21: 2 | FB21: 0 | FC21: 1.8 | FD21: =EZ21*FA21 -> 3.6 | FG21: Rear | FH21: 0.13 | FI21: 0.13 | FJ21: 0.3 | FK21: 2.3 | FL21: =FH21*FI21 -> 0.0169 | FO21: Front | FP21: 0.13 | FQ21: 0.13 | FR21: 1.8 | FS21: 2.3 | FT21: =FP21*FQ21 -> 0.0169 | FW21: Front
